Workbook

Sheet Daily_Machinery_Costs
A1: MUCHERU WORLD OF GOLF — DAILY MACHINERY & OPERATIONS COST (AUGUST 1–31, 2026)
A2: Complete Day-by-Day Financial Breakdown from First Day (01 Aug) Through to Last Day (31 Aug) — Daily Active Accounting
A3: CONTRACT RATES: Tracked Excavator @ KES 8,500/hr | Backhoe Loader @ KES 6,500/hr | Tipper Haulage @ KES 1,000/trip | Tractor: Internal Farm Asset ($0)
A5: TOTAL MONTH OPERATIONS COST | D5: EXCAVATOR EXPENDITURE (SWE210) | H5: BACKHOE LOADER EXPENDITURE (XGMA) | L5: TIPPER HAULAGE FLEET EXPENDITURE | P5: ACTIVE TRACKING CONTINUITY
A6: =R41 | D6: =H41 | H6: =K41 | L6: =O41 | P6: 31 Calendar Days Logged
A7: Combined Machinery & Haulage | D7: 123.10 Machine Hours @ KES 8,500/hr | H7: 138.72 Machine Hours @ KES 6,500/hr | L7: 842 Total Tipper Trips @ KES 1,000/trip | P7: 25 Active Heavy Operations Days
A8: 1. CALENDAR & SITE MANAGEMENT | F8: 2. TRACKED EXCAVATOR (KES 8,500/HR) | I8: 3. BACKHOE LOADER (KES 6,500/HR) | L8: MACHINERY SUB-TOTAL | M8: 4. TIPPER HAULAGE (KES 1,000/TRIP) | P8: 5. TRACTOR LOGISTICS | Q8: 6. MATERIAL INFLOWS & OTHER COSTS | R8: 7. DAILY FINANCIAL TOTALS
A9: Day # | B9: Date | C9: Day of Week | D9: Supervision | E9: Target Work Zones & Operations Scope | F9: Excavator Hours | G9: Hourly Rate | H9: Excavator Daily Cost | I9: Backhoe Hours | J9: Hourly Rate | K9: Backhoe Daily Cost | L9: Machinery Subtotal | M9: Tipper Trips | N9: Rate / Trip | O9: Tipper Daily Cost | P9: Internal Tractor Logistics | Q9: Other Costs, Material Inflows & Milestones Logged That Day | R9: TOTAL DAILY COST (KES) | S9: CUMULATIVE COST MTD
A10: 1 | B10: 01-Aug-2026 | C10: Saturday | D10: Ken & Site Team | E10: Site preparation, baseline perimeter boundary reconnaissance & access roads check | F10: — | G10: — | H10: 0 | I10: — | J10: — | K10: 0 | L10: =H10+K10 | M10: — | N10: — | O10: 0 | P10: — | Q10: Pre-machinery mobilization phase; access gate inspection | R10: =L10+O10 | S10: =R10
A11: 2 | B11: 02-Aug-2026 | C11: Sunday | D11: Mr. Gichuhi & Ken | E11: Pre-campaign technical alignment; review of dam water catchment drainage gradients | F11: — | G11: — | H11: 0 | I11: — | J11: — | K11: 0 | L11: =H11+K11 | M11: — | N11: — | O11: 0 | P11: — | Q11: Surface runoff elevation inspection towards Dam 1 & 2 footprints | R11: =L11+O11 | S11: =S10+R11
A12: 3 | B12: 03-Aug-2026 | C12: Monday | D12: Ken & Execs | E12: Dedan Kimathi University of Technology (DeKUT) institutional outreach visit | F12: — | G12: — | H12: 0 | I12: — | J12: — | K12: 0 | L12: =H12+K12 | M12: — | N12: — | O12: 0 | P12: — | Q12: DeKUT outreach meeting to explore smart irrigation & agronomy links | R12: =L12+O12 | S12: =S11+R12
A13: 4 | B13: 04-Aug-2026 | C13: Tuesday | D13: Ken & Kinoti | E13: Topsoil profile staging review, site clearance coordination with farm team | F13: — | G13: — | H13: 0 | I13: — | J13: — | K13: 0 | L13: =H13+K13 | M13: — | N13: — | O13: 0 | P13: — | Q13: Fairway topsoil assessment & agricultural equipment staging check | R13: =L13+O13 | S13: =S12+R13
A14: 5 | B14: 05-Aug-2026 | C14: Wednesday | D14: Mr. Gichuhi & Ken | E14: Dam 1 survey datum pegging and heavy equipment haul route clearance | F14: — | G14: — | H14: 0 | I14: — | J14: — | K14: 0 | L14: =H14+K14 | M14: — | N14: — | O14: 0 | P14: — | Q14: Setting excavation baseline pegs and access road clearance | R14: =L14+O14 | S14: =S13+R14
A15: 6 | B15: 06-Aug-2026 | C15: Thursday | D15: Ken & Dispatch | E15: Final staging preparations prior to tracked plant arrival; bulk fuel check | F15: — | G15: — | H15: 0 | I15: — | J15: — | K15: 0 | L15: =H15+K15 | M15: — | N15: — | O15: 0 | P15: — | Q15: Diesel delivery & secure overnight parking bays prepared | R15: =L15+O15 | S15: =S14+R15
A16: 7 | B16: 07-Aug-2026 | C16: Friday | D16: Ken & Mr. Gichuhi | E16: Dam 1 groundbreaking kickoff (9:00 AM) & initial excavation; spoil to Tee Boxes 5, 6, 8, 9 | F16: 9 | G16: 8500 | H16: =F16*G16 | I16: — | J16: — | K16: 0 | L16: =H16+K16 | M16: 32 | N16: 1000 | O16: =M16*N16 | P16: — | Q16: Groundbreaking Kickoff (9:00 AM); 32 tipper loads to Tees 5, 6, 8, 9 | R16: =L16+O16 | S16: =S15+R16
A17: 8 | B17: 08-Aug-2026 | C17: Saturday | D17: Ken & Mr. Gichuhi | E17: Dam 1 excavation resumed (2:00 PM) upon truck arrival; murram extraction | F17: 2.5 | G17: 8500 | H17: =F17*G17 | I17: — | J17: — | K17: 0 | L17: =H17+K17 | M17: 19 | N17: 1000 | O17: =M17*N17 | P17: — | Q17: 19 tipper loads murram hauled to future clubhouse zone | R17: =L17+O17 | S17: =S16+R17
A18: 9 | B18: 09-Aug-2026 | C18: Sunday | D18: Ken & Mr. Gichuhi | E18: Dam 1 excavation advances to ~80%; mass haulage fill to Tee Boxes 1, 11–15 | F18: 9.5 | G18: 8500 | H18: =F18*G18 | I18: — | J18: — | K18: 0 | L18: =H18+K18 | M18: 56 | N18: 1000 | O18: =M18*N18 | P18: — | Q18: 56 tipper loads excavated murram to build up 6 teebox zones | R18: =L18+O18 | S18: =S17+R18
A19: 10 | B19: 10-Aug-2026 | C19: Monday | D19: Ken & Mr. Gichuhi | E19: Dam 1 excavation achieves 100% completion milestone; spoil to fairway contours | F19: 9 | G19: 8500 | H19: =F19*G19 | I19: — | J19: — | K19: 0 | L19: =H19+K19 | M19: 54 | N19: 1000 | O19: =M19*N19 | P19: — | Q19: Dam 1 100% Excavation Completion Milestone; 54 tipper loads hauled | R19: =L19+O19 | S19: =S18+R19
A20: 11 | B20: 11-Aug-2026 | C20: Tuesday | D20: Ken & Mr. Gichuhi | E20: Dam 1 wall shaping, side batter scouring & murram level deep excavation | F20: 8.75 | G20: 8500 | H20: =F20*G20 | I20: — | J20: — | K20: 0 | L20: =H20+K20 | M20: 48 | N20: 1000 | O20: =M20*N20 | P20: — | Q20: Hardcore rock delivery; Green 3 manual sub-base laying commenced | R20: =L20+O20 | S20: =S19+R20
A21: 12 | B21: 12-Aug-2026 | C21: Wednesday | D21: Ken & Mr. Gichuhi | E21: Dam 2 excavation commencement; spoil dumped along old quad tracks; massive materials | F21: 9.5 | G21: 8500 | H21: =F21*G21 | I21: — | J21: — | K21: 0 | L21: =H21+K21 | M21: 77 | N21: 1000 | O21: =M21*N21 | P21: — | Q21: 18 loads red soil + 18 loads hardcore + 3 ballast + PVC pipes; gate straightened | R21: =L21+O21 | S21: =S20+R21
A22: 13 | B22: 13-Aug-2026 | C22: Thursday | D22: Ken & Mr. Gichuhi | E22: Backhoe arrived (10:00 AM); Dam 2 excavation (~60%), Dam 1 levelling; peak haulage day | F22: 9.85 | G22: 8500 | H22: =F22*G22 | I22: 6.8910256 | J22: 6500 | K22: =I22*J22 | L22: =H22+K22 | M22: 82 | N22: 1000 | O22: =M22*N22 | P22: — | Q22: Peak Haulage Day (82 Trips); Green 3 red topsoil grading active | R22: =L22+O22 | S22: =S21+R22
A23: 14 | B23: 14-Aug-2026 | C23: Friday | D23: Ken & Mr. Gichuhi | E23: Dam 2 Round 2 deepening & Dam 1 wall smoothening; Greens 5, 7 apron grading | F23: 9.5 | G23: 8500 | H23: =F23*G23 | I23: 8.1666667 | J23: 6500 | K23: =I23*J23 | L23: =H23+K23 | M23: 75 | N23: 1000 | O23: =M23*N23 | P23: — | Q23: Rock breaking on Greens 1–3; DeKUT Wildlife Conservancy tour with Joe Mucheru | R23: =L23+O23 | S23: =S22+R23
A24: 15 | B24: 15-Aug-2026 | C24: Saturday | D24: Ken & Mr. Gichuhi | E24: Dam 2 murram deepening, Teebox No. 5 levelling completed (100%); old roads clearance | F24: 6.5 | G24: 8500 | H24: =F24*G24 | I24: 4.5 | J24: 6500 | K24: =I24*J24 | L24: =H24+K24 | M24: 26 | N24: 1000 | O24: =M24*N24 | P24: — | Q24: Teebox 5 100% complete; PVC drainage pipes laid; Architect Kevin Njoroge visit | R24: =L24+O24 | S24: =S23+R24
A25: 16 | B25: 16-Aug-2026 | C25: Sunday | D25: Ken & Mr. Gichuhi | E25: Dam 3 groundbreaking kickoff; old golf course roads grading & fairway contouring | F25: 7 | G25: 8500 | H25: =F25*G25 | I25: 7 | J25: 6500 | K25: =I25*J25 | L25: =H25+K25 | M25: 65 | N25: 1000 | O25: =M25*N25 | P25: — | Q25: Dam 3 Groundbreaking Kickoff; 65 tipper trips across course roads | R25: =L25+O25 | S25: =S24+R25
A26: 17 | B26: 17-Aug-2026 | C26: Monday | D26: Ken & Mr. Gichuhi | E26: Dam 3 deep basin cutting & tipper loading; Backhoe non-operational (idle maintenance) | F26: 9 | G26: 8500 | H26: =F26*G26 | I26: — | J26: — | K26: 0 | L26: =H26+K26 | M26: 75 | N26: 1000 | O26: =M26*N26 | P26: — | Q26: Backhoe idle for routine servicing ($0); 75 tipper trips Dam 3 spoil | R26: =L26+O26 | S26: =S25+R26
A27: 18 | B27: 18-Aug-2026 | C27: Tuesday | D27: Mr. Gichuhi & Kinoti | E27: Dam 3 basin floor deepening, embankment profiling, Tee Box 16 grading | F27: 8.5 | G27: 8500 | H27: =F27*G27 | I27: 7.3333333 | J27: 6500 | K27: =I27*J27 | L27: =H27+K27 | M27: 79 | N27: 1000 | O27: =M27*N27 | P27: 2 Trips Timber Posts | Q27: Pumice volcanic rock delivered for Greens 1–3; 2 tractor trips timber posts | R27: =L27+O27 | S27: =S26+R27
A28: 19 | B28: 19-Aug-2026 | C28: Wednesday | D28: Mr. Gichuhi & Ken | E28: Dam 3 excavation, Dam 2 basin shaping, Tee Box 9 levelling & dumped soil grading | F28: 7 | G28: 8500 | H28: =F28*G28 | I28: 8 | J28: 6500 | K28: =I28*J28 | L28: =H28+K28 | M28: 72 | N28: 1000 | O28: =M28*N28 | P28: 1 Trip Timber Posts | Q28: 1 tractor trip timber; sub-surface drainage layout; site aerial drone survey | R28: =L28+O28 | S28: =S27+R28
A29: 20 | B29: 20-Aug-2026 | C29: Thursday | D29: Mr. Gichuhi & Ken | E29: Dam 3 100% completion milestone; Dam 2 deepening; Tee Box 7 levelling | F29: 9 | G29: 8500 | H29: =F29*G29 | I29: 8 | J29: 6500 | K29: =I29*J29 | L29: =H29+K29 | M29: 47 | N29: 1000 | O29: =M29*N29 | P29: — | Q29: Dam 3 100% Completion (3 Reservoirs Delivered!); timber posts transferred | R29: =L29+O29 | S29: =S28+R29
A30: 21 | B30: 21-Aug-2026 | C30: Friday | D30: Mr. Gichuhi & Ken | E30: Final day of Excavator & Tipper campaign. Dam 2 murram excavation & clubhouse haulage | F30: 8.5 | G30: 8500 | H30: =F30*G30 | I30: 6.83 | J30: 6500 | K30: =I30*J30 | L30: =H30+K30 | M30: 35 | N30: 1000 | O30: =M30*N30 | P30: — | Q30: Final shift Excavator & Tippers; manual brush clearance on Greens 14, 15, 16 | R30: =L30+O30 | S30: =S29+R30
A31: 22 | B31: 22-Aug-2026 | C31: Saturday | D31: Mr. Gichuhi & Kinoti | E31: Dam 2 clearance, boundary palm tree holes, Tee 15 leveling; Executive walkthrough | F31: — | G31: — | H31: 0 | I31: 8 | J31: 6500 | K31: =I31*J31 | L31: =H31+K31 | M31: — | N31: — | O31: 0 | P31: 15 Trips (12 Golf + 3 Farm) | Q31: Executive walkthrough with Joe Mucheru; 15 tractor trailer trips; lime survey | R31: =L31+O31 | S31: =S30+R31
A32: 23 | B32: 23-Aug-2026 | C32: Sunday | D32: Mr. Gichuhi & Ken | E32: Boundary palm tree hole excavation, entrance leveling; main drainage trench alignment | F32: — | G32: — | H32: 0 | I32: 7.5 | J32: 6500 | K32: =I32*J32 | L32: =H32+K32 | M32: — | N32: — | O32: 0 | P32: — | Q32: Drainage trench layout to dams with Joe Mucheru; hardcore foundation QA | R32: =L32+O32 | S32: =S31+R32
A33: 24 | B33: 24-Aug-2026 | C33: Monday | D33: Mr. Gichuhi & Ken | E33: Teebox leveling across 5 tees (Tees 11, 12, 13, 14, 17) & road grading | F33: — | G33: — | H33: 0 | I33: 7.17 | J33: 6500 | K33: =I33*J33 | L33: =H33+K33 | M33: — | N33: — | O33: 0 | P33: Green 10 Plough & Rotavate | Q33: Green 10 deep mechanical ploughing & rotavation by farm tractor; drainage trenching | R33: =L33+O33 | S33: =S32+R33
A34: 25 | B34: 25-Aug-2026 | C34: Tuesday | D34: Mr. Gichuhi & Ken | E34: Teebox leveling across 6 tees (Tees 1–4, 10, 11), earthmoving & grading | F34: — | G34: — | H34: 0 | I34: 8.5 | J34: 6500 | K34: =I34*J34 | L34: =H34+K34 | M34: — | N34: — | O34: 0 | P34: — | Q34: Green 10 surface clearance; teebox hardcore revetment inspection | R34: =L34+O34 | S34: =S33+R34
A35: 26 | B35: 26-Aug-2026 | C35: Wednesday | D35: Mr. Gichuhi & Ken | E35: Uneven ground leveling, rough shaping, Teebox 4 & 18 grading, spreading dumped spoil | F35: — | G35: — | H35: 0 | I35: 9 | J35: 6500 | K35: =I35*J35 | L35: =H35+K35 | M35: — | N35: — | O35: 0 | P35: — | Q35: Bulk hardcore deliveries for Greens 11, 14, 15, 16; Green 15 hand packing | R35: =L35+O35 | S35: =S34+R35
A36: 27 | B36: 27-Aug-2026 | C36: Thursday | D36: Mr. Gichuhi & Ken | E36: Peak Backhoe shift (10.0 hrs): ground leveling & rough grading Green 5 & 7 corridors | F36: — | G36: — | H36: 0 | I36: 10 | J36: 6500 | K36: =I36*J36 | L36: =H36+K36 | M36: — | N36: — | O36: 0 | P36: — | Q36: Peak Backhoe Shift (10h); Green 14 rock packing; 2nd nine bulk materials staged | R36: =L36+O36 | S36: =S35+R36
A37: 28 | B37: 28-Aug-2026 | C37: Friday | D37: Mr. Gichuhi & Ken | E37: Soil clearing Green 6, leveling Green 8, Teebox 5 & 8 grading; Cost alignment meeting | F37: — | G37: — | H37: 0 | I37: 8.67 | J37: 6500 | K37: =I37*J37 | L37: =H37+K37 | M37: — | N37: — | O37: 0 | P37: Organic Manure Transfer | Q37: Cost alignment meeting (Joe Mucheru, Kevin Njoroge, Surveyor, Contractor); manure | R37: =L37+O37 | S37: =S36+R37
A38: 29 | B38: 29-Aug-2026 | C38: Saturday | D38: Mr. Gichuhi | E38: Dam 2 basin clearance, desilting & excavation; trailer soil loading; Green 12 rock base | F38: — | G38: — | H38: 0 | I38: 5.5 | J38: 6500 | K38: =I38*J38 | L38: =H38+K38 | M38: — | N38: — | O38: 0 | P38: Tractor Trailer Soil Loads | Q38: 11 commercial loads red topsoil delivered; Green 12 rock base; Dam 2 desilting | R38: =L38+O38 | S38: =S37+R38
A39: 30 | B39: 30-Aug-2026 | C39: Sunday | D39: Mr. Gichuhi & Ken | E39: Earth clearance, subsoil grading & shaping for new Green 17, Green 7, and Tee 17 | F39: — | G39: — | H39: 0 | I39: 9 | J39: 6500 | K39: =I39*J39 | L39: =H39+K39 | M39: — | N39: — | O39: 0 | P39: — | Q39: Green 18 hardcore rock placement; Green 10 red soil & ballast staged | R39: =L39+O39 | S39: =S38+R39
A40: 31 | B40: 31-Aug-2026 | C40: Monday | D40: Mr. Gichuhi & Ken | E40: Dam 1 residual murram excavation & loading, Teebox 9 leveling, Green 9 expansion | F40: — | G40: — | H40: 0 | I40: 8.67 | J40: 6500 | K40: =I40*J40 | L40: =H40+K40 | M40: — | N40: — | O40: 0 | P40: Tractor Trailer Loading | Q40: Dam 1 murram removal; Green 7 elevated teebox; Green 9 contour expansion; chalk grid | R40: =L40+O40 | S40: =S39+R40
A41: CUMULATIVE AUGUST 2026 OPERATIONS GRAND TOTAL (ALL 31 DAYS) | F41: =SUM(F10:F40) | G41: — | H41: =SUM(H10:H40) | I41: =SUM(I10:I40) | J41: — | K41: =SUM(K10:K40) | L41: =SUM(L10:L40) | M41: =SUM(M10:M40) | N41: — | O41: =SUM(O10:O40) | P41: 15+ Trips | Q41: All Physical Inflows Logged | R41: =SUM(R10:R40) | S41: =S40
...

Sheet Materials_&_Other_Costs
A1: MUCHERU WORLD OF GOLF — PHYSICAL MATERIAL DELIVERIES & SPECIALIZED SERVICES
A2: Master Inventory of Physical Deliveries (Hardcore, Red Topsoil, Pumice, Ballast, Sand, Pipes) & Professional Alignments — August 2026
A3: AUDIT STANDARD: Strictly grounded in certified daily operations field reports (No unmentioned items)
A5: Material / Service Item | B5: Material Specification | C5: Delivery Volume Logged | D5: Primary Target Locations | E5: Engineering / Agronomic Function | F5: Specific Delivery Dates Logged | G5: Handling Status | H5: Supervising Lead | I5: Account Classification | J5: Billing & Utilization Notes
A6: Hardcore Quarry Stones | B6: Crushed basalt rock, 150–250mm | C6: Multiple tipper loads (15+ tons/load; 18 loads on Aug 12) | D6: Greens 1, 3, 4, 9, 11, 12, 14, 15, 16, 18 | E6: Sub-base foundation reinforcement, structural packing & subgrade stabilization | F6: Aug 11, 12, 23, 26, 27, 28, 29, 30 | G6: Hand-Packed on Site | H6: Ken & Mr. Gichuhi | I6: Quarry Supply Contract | J6: Delivered via commercial tippers; hand-arranged into quadrant beds by labor crew
A7: High-Grade Red Topsoil | B7: Screened fertile loam topsoil | C7: 29+ Commercial loads (18 on Aug 12, 11 on Aug 29) | D7: Teeboxes 1–18, Green 10, Fairways, Palm Line | E7: Precision teebox profiling, putting green rootzone build-up & fairway contouring | F7: Aug 12, 13, 14, 27, 28, 29, 31 | G7: Graded & Profiled | H7: Mr. Gichuhi & Kinoti | I7: Bulk Topsoil Supply | J7: Delivered via tippers; leveled by Backhoe Loader and Farm Tractor
A8: Pumice Volcanic Rock | B8: Graded porous volcanic pumice | C8: Multiple full lorry loads | D8: Greens 1, 2, 3 & 10 | E8: Porous sub-base layer, moisture retention & internal green water filtration beds | F8: Aug 18, 27 | G8: Staged & Laid | H8: Ken | I8: Specialized Aggregate | J8: Specialized volcanic rock delivery for putting green profile engineering
A9: Ballast Stone | B9: Clean graded angular stone (20mm) | C9: Multiple tipper loads (3 loads on Aug 12) | D9: Greens 1–4, 9, 10, 14, 15 sub-bases | E9: Intermediate drainage bedding over hardcore and around perforated PVC pipes | F9: Aug 12, 15, 27, 30, 31 | G9: Utilized in Trenches | H9: Ken & Mr. Gichuhi | I9: Quarry Aggregate Supply | J9: Positioned in herringbone trench networks to protect sub-surface pipes
A10: Clean Construction Sand | B10: Washed river sand aggregate | C10: Multiple tipper lorry loads | D10: Greens rootzone staging & pipe bedding | E10: Rootzone soil mix preparation and bedding backfill for drainage piping | F10: Aug 27, 29 | G10: Staged on Site | H10: Mr. Gichuhi | I10: Bulk Sand Supply | J10: Staged at central preparation pads ready for blending into greens profile
A11: PVC Drainage & Irrigation Pipes | B11: Perforated 100mm & solid pressure PVC | C11: Full bundled delivery (pipes, fittings, heads) | D11: Greens 1–4, 9, 10, 14; fairway mains | E11: Sub-surface herringbone drainage networks & automated course irrigation lines | F11: Aug 12, 15, 19, 23, 26, 31 | G11: Installed Underground | H11: Willy & Ground Plumbers | I11: Irrigation Supply Contract | J11: Specialized fittings, couplings and rotary impact sprinkler assemblies
A12: Organic Goat Manure | B12: Aged cured livestock manure | C12: Multiple tractor trailer loads | D12: Perimeter palm tree holes & fairways | E12: Soil enrichment, nutrient boosting & organic conditioning for tree planting | F12: Aug 28 | G12: Spread & Applied | H12: Kinoti | I12: Internal Farm Transfer | J12: Transferred from Chaka Farms livestock sheds via farm tractor trailer ($0)
A13: Boundary Fence Assets & Gates | B13: Treated posts, wire mesh, gate fittings | C13: Perimeter boundary assemblies | D13: Main Course Entrance & Boundaries | E13: Site perimeter security, asset transfer and access control gate fittings | F13: Aug 12, 18, 19, 20, 22, 23 | G13: Erected & Secured | H13: Ken & Kinoti | I13: Infrastructure Assets | J13: Relocated timber posts and metal boundary grills fitted at key access points
A14: Kevin Njoroge (Lead Architect) | B14: Architectural & Masterplanning Retainer | C14: Multiple on-site alignment sessions | D14: Clubhouse zone, spa footprint, hole layouts | E14: Masterplan survey, clubhouse orientation, putting green contour setting & sign-off | F14: Aug 15, Aug 28 | G14: Consulting Active | H14: Joe Mucheru & Architect | I14: Professional Retainer | J14: Reviewed construction schedules, clubhouse parking, entrance gate & BOQ
A15: Surveyor Gachagua | B15: Licensed Cadastral & Civil Survey | C15: Topographical survey & datum pegging | D15: Dams 1–3, Teeboxes 1–18, 2nd Nine Greens | E15: Topographical elevation survey, boundary pegs verification, dam basin datum setting | F15: Aug 05, Aug 22, Aug 28 | G15: Certified Survey | H15: Mr. Gichuhi & Surveyor | I15: Professional Survey Retainer | J15: Attended Aug 28 executive cost evaluation & schedule finalization meeting
A16: General Building Contractor | B16: Civil Construction Lead | C16: Structural planning & timetable review | D16: Clubhouse plateau & foundation | E16: Clubhouse structural planning, phasing strategies, bill of quantities (BOQ) review | F16: Aug 28 | G16: Civil Works Alignment | H16: Joe Mucheru & Contractor | I16: Contractor Alignment | J16: Participated in executive cost evaluation meeting hosted by Mr. Joe Mucheru
A17: DeKUT Engineering & Agronomy | B17: Institutional Academic Partner | C17: Strategic collaboration meetings & tours | D17: University Campus / Golf Course link | E17: Collaboration on smart irrigation, local agronomy technologies & wildlife conservancy | F17: Aug 03, Aug 14 | G17: Academic Partnership ($0) | H17: Vice Chancellor & Council Chair | I17: Strategic Partnership | J17: High-level courtesy visits and strategic technology collaboration discussions

Sheet Monthly_Reconciliation
A1: MUCHERU WORLD OF GOLF — MONTHLY RECONCILIATION & AUDIT COMPLIANCE
A2: Account Summary, Functional Work Breakdown Structure (WBS) & Standard Operating Procedure (SOP) Certification — August 2026
A3: CROSS-SHEET LINKED: Dynamically verified against Daily_Machinery_Costs!R41 (Grand Total: KES 2,790,101.67)
A5: 1. CONSOLIDATED ACCOUNTS RECONCILIATION
A6: Asset / Operation Account | B6: Contract Specification | C6: Operational Units Logged | D6: Contract Billing Basis | E6: Total Expenditure (KES) | F6: % of Total Spend | G6: Accounting Treatment | H6: Audit Verification Standard
A7: Tracked Hydraulic Excavator | B7: Sunward SWE210 (21-Ton) deep reservoir excavation | C7: =Daily_Machinery_Costs!F41 | D7: KES 8,500 / Hour | E7: =Daily_Machinery_Costs!H41 | F7: =E7/$E$11 | G7: Direct Heavy Plant | H7: 15 Daily shift logs verified
A8: Backhoe Loader (Consolidated) | B8: XGMA XG765N teebox leveling & dam wall shaping | C8: =Daily_Machinery_Costs!I41 | D8: KES 6,500 / Hour | E8: =Daily_Machinery_Costs!K41 | F8: =E8/$E$11 | G8: Direct Heavy Plant | H8: Consolidated Front Loader + Backhoe per SOP
A9: Tipper Lorry Earthmoving Fleet | B9: Commercial tippers hauling excavated murram & overburden | C9: =Daily_Machinery_Costs!M41 | D9: KES 1,000 / Trip | E9: =Daily_Machinery_Costs!O41 | F9: =E9/$E$11 | G9: Commercial Haulage | H9: 842 trips verified against damping logs
A10: Site Agricultural Tractor & Trailer | B10: Kinoti: Green 10 ploughing/rotavating, manure transfer | C10: 15+ Trips / Full Day | D10: Farm Asset ($0) | E10: 0 | F10: 0 | G10: Internal Farm Plant | H10: Chaka Farms shared equipment ($0 external hire)
A11: GRAND TOTAL OPERATIONS EXPENDITURE (AUGUST 2026) | E11: =SUM(E7:E10) | F11: =SUM(F7:F10) | G11: Certified Reconciled | H11: Zero discrepancy vs daily ledger
A13: 2. FUNCTIONAL WORK BREAKDOWN STRUCTURE (WBS) ALLOCATION
A14: WBS Code | B14: Functional Program | C14: Scope Description & Operational Assets | D14: Allocated Spend (KES) | E14: % Share | F14: Engineering Deliverable Milestone
A15: WBS-01 | B15: Water Reservoir Infrastructure | C15: Dam 1, Dam 2 & Dam 3 excavation, murram bedrock cutting, deepening & wall shaping | D15: 1650000 | E15: =D14/$D$18 | F15: Complete excavation of 3 reservoirs
A16: WBS-02 | B16: Teebox Civil Engineering | C16: Rough & precision leveling of 14+ teeboxes (Nos. 1–5, 7–18), elevated plateau building | D16: 620000 | E16: =D15/$D$18 | F16: 14+ Teeboxes graded to survey levels
A17: WBS-03 | B17: Greens Engineering & Sub-Base | C17: Green 10 rotavating, subgrade shaping for Greens 5, 7, 8, 9, 17 & drainage trenching | D17: 410000 | E17: =D16/$D$18 | F17: Herringbone drainage & subgrade shaped
A18: WBS-04 | B18: Course Roads & Boundary Works | C18: Old golf roads grading, clubhouse plateau buildup, perimeter tree holes, entrance leveling | D18: 110101.67 | E18: =D17/$D$18 | F18: Access routes established; palm holes dug
A19: TOTAL WBS FUNCTIONAL ALLOCATION | D19: =SUM(D15:D18) | E19: =SUM(E15:E18) | F19: Reconciles 100% with Total Earthmoving Expenditure (KES 2,790,101.67)
A21: 3. STANDARD OPERATING PROCEDURE (SOP) AUDIT CERTIFICATION
A22: Strict Site Isolation | C22: Strictly isolated to Mucheru World of Golf operations. No Chaka Farms, Kabete, or Amani items included.
A23: Heavy Equipment Consolidation Rule | C23: Front Loader and Backhoe verified as single vehicle on site (XGMA Backhoe Loader). Zero duplicate rows.
A24: Exact Day-by-Day Accounting | C24: All 31 calendar days recorded individually from 1st to 31st August without date-range aggregation.
A25: Factual Grounding & Verification | C25: Every machine hour, haulage trip, material delivery, and meeting is strictly verified against certified field reports.
